<sdf version='1.6'>
  <world name='default'>
  <plugin name="hello" filename="libhello.so"/>
    <light name='sun' type='directional'>
      <cast_shadows>1</cast_shadows>
      <pose frame=''>0 0 10 0 -0 0</pose>
      <diffuse>0.8 0.8 0.8 1</diffuse>
      <specular>0.2 0.2 0.2 1</specular>
      <attenuation>
        <range>1000</range>
        <constant>0.9</constant>
        <linear>0.01</linear>
        <quadratic>0.001</quadratic>
      </attenuation>
      <direction>-0.5 0.1 -0.9</direction>
    </light>
    <model name='ground_plane'>
      <static>1</static>
      <link name='link'>
        <collision name='collision'>
          <geometry>
            <plane>
              <normal>0 0 1</normal>
              <size>100 100</size>
            </plane>
          </geometry>
          <surface>
            <contact>
              <collide_bitmask>65535</collide_bitmask>
              <ode/>
            </contact>
            <friction>
              <ode>
                <mu>100</mu>
                <mu2>50</mu2>
              </ode>
              <torsional>
                <ode/>
              </torsional>
            </friction>
            <bounce/>
          </surface>
          <max_contacts>10</max_contacts>
        </collision>
        <visual name='visual'>
          <cast_shadows>0</cast_shadows>
          <geometry>
            <plane>
              <normal>0 0 1</normal>
              <size>100 100</size>
            </plane>
          </geometry>
          <material>
            <script>
              <uri>file://media/materials/scripts/gazebo.material</uri>
              <name>Gazebo/Grey</name>
            </script>
          </material>
        </visual>
        <self_collide>0</self_collide>
        <kinematic>0</kinematic>
      </link>
    </model>
    <gravity>0 0 -9.8</gravity>
    <magnetic_field>6e-06 2.3e-05 -4.2e-05</magnetic_field>
    <atmosphere type='adiabatic'/>
    <physics name='default_physics' default='0' type='ode'>
      <max_step_size>0.001</max_step_size>
      <real_time_factor>1</real_time_factor>
      <real_time_update_rate>1000</real_time_update_rate>
    </physics>
    <scene>
      <ambient>0.4 0.4 0.4 1</ambient>
      <background>0.7 0.7 0.7 1</background>
      <shadows>1</shadows>
    </scene>
    <spherical_coordinates>
      <surface_model>EARTH_WGS84</surface_model>
      <latitude_deg>0</latitude_deg>
      <longitude_deg>0</longitude_deg>
      <elevation>0</elevation>
      <heading_deg>0</heading_deg>
    </spherical_coordinates>
    <model name='two_wheeled_robot'>
      <model name='create'>
        <link name='base'>
          <inertial>
            <pose frame=''>0.001453 -0.000453 0.029787 0 -0 0</pose>
            <inertia>
              <ixx>0.05864</ixx>
              <ixy>0.000124</ixy>
              <ixz>0.000615</ixz>
              <iyy>0.058786</iyy>
              <iyz>1.4e-05</iyz>
              <izz>1.53244</izz>
            </inertia>
            <mass>2.234</mass>
          </inertial>
          <collision name='base_collision'>
            <pose frame=''>0 0 0.0478 0 -0 0</pose>
            <geometry>
              <cylinder>
                <radius>0.016495</radius>
                <length>0.061163</length>
              </cylinder>
            </geometry>
            <max_contacts>10</max_contacts>
            <surface>
              <contact>
                <ode/>
              </contact>
              <bounce/>
              <friction>
                <torsional>
                  <ode/>
                </torsional>
                <ode/>
              </friction>
            </surface>
          </collision>
          <visual name='base_visual'>
            <pose frame=''>0 0 0.0478 0 -0 0</pose>
            <geometry>
              <mesh>
                <uri>model://create/meshes/create_body.dae</uri>
              </mesh>
            </geometry>
          </visual>
          <collision name='front_wheel_collision'>
            <pose frame=''>0.13 0 0.017 -0 1.5707 1.5707</pose>
            <geometry>
              <sphere>
                <radius>0.018</radius>
              </sphere>
            </geometry>
            <surface>
              <friction>
                <ode>
                  <mu>0</mu>
                  <mu2>0</mu2>
                  <fdir1>0 0 0</fdir1>
                  <slip1>0</slip1>
                  <slip2>0</slip2>
                </ode>
                <torsional>
                  <ode/>
                </torsional>
              </friction>
              <contact>
                <ode/>
              </contact>
              <bounce/>
            </surface>
            <max_contacts>10</max_contacts>
          </collision>
          <visual name='front_wheel_visual'>
            <pose frame=''>0.13 0 0.017 -0 1.5707 1.5707</pose>
            <geometry>
              <sphere>
                <radius>0.009</radius>
              </sphere>
            </geometry>
          </visual>
          <collision name='rear_wheel_collision'>
            <pose frame=''>-0.13 0 0.017 -0 1.5707 1.5707</pose>
            <geometry>
              <sphere>
                <radius>0.015</radius>
              </sphere>
            </geometry>
            <surface>
              <friction>
                <ode>
                  <mu>0</mu>
                  <mu2>0</mu2>
                  <fdir1>0 0 0</fdir1>
                  <slip1>0</slip1>
                  <slip2>0</slip2>
                </ode>
                <torsional>
                  <ode/>
                </torsional>
              </friction>
              <contact>
                <ode/>
              </contact>
              <bounce/>
            </surface>
            <max_contacts>10</max_contacts>
          </collision>
          <visual name='rear_wheel_visual'>
            <pose frame=''>-0.13 0 0.017 -0 1.5707 1.5707</pose>
            <geometry>
              <sphere>
                <radius>0.0075</radius>
              </sphere>
            </geometry>
          </visual>
          <sensor name='left_cliff_sensor' type='ray'>
            <pose frame=''>0.07 0.14 0.027 0 1.57079 0</pose>
            <ray>
              <scan>
                <horizontal>
                  <samples>1</samples>
                  <resolution>1</resolution>
                  <min_angle>0</min_angle>
                  <max_angle>0</max_angle>
                </horizontal>
                <vertical>
                  <samples>1</samples>
                  <min_angle>0</min_angle>
                  <max_angle>0</max_angle>
                </vertical>
              </scan>
              <range>
                <min>0.01</min>
                <max>0.04</max>
                <resolution>0.1</resolution>
              </range>
            </ray>
          </sensor>
          <sensor name='leftfront_cliff_sensor' type='ray'>
            <pose frame=''>0.15 0.04 0.027 0 1.57079 0</pose>
            <ray>
              <scan>
                <horizontal>
                  <samples>1</samples>
                  <resolution>1</resolution>
                  <min_angle>0</min_angle>
                  <max_angle>0</max_angle>
                </horizontal>
                <vertical>
                  <samples>1</samples>
                  <min_angle>0</min_angle>
                  <max_angle>0</max_angle>
                </vertical>
              </scan>
              <range>
                <min>0.01</min>
                <max>0.04</max>
                <resolution>0.1</resolution>
              </range>
            </ray>
          </sensor>
          <sensor name='right_cliff_sensor' type='ray'>
            <pose frame=''>0.07 -0.14 0.027 0 1.57079 0</pose>
            <ray>
              <scan>
                <horizontal>
                  <samples>1</samples>
                  <resolution>1</resolution>
                  <min_angle>0</min_angle>
                  <max_angle>0</max_angle>
                </horizontal>
                <vertical>
                  <samples>1</samples>
                  <min_angle>0</min_angle>
                  <max_angle>0</max_angle>
                </vertical>
              </scan>
              <range>
                <min>0.01</min>
                <max>0.04</max>
                <resolution>0.1</resolution>
              </range>
            </ray>
          </sensor>
          <sensor name='rightfront_cliff_sensor' type='ray'>
            <pose frame=''>0.15 -0.04 0.027 0 1.57079 0</pose>
            <ray>
              <scan>
                <horizontal>
                  <samples>1</samples>
                  <resolution>1</resolution>
                  <min_angle>0</min_angle>
                  <max_angle>0</max_angle>
                </horizontal>
                <vertical>
                  <samples>1</samples>
                  <min_angle>0</min_angle>
                  <max_angle>0</max_angle>
                </vertical>
              </scan>
              <range>
                <min>0.01</min>
                <max>0.04</max>
                <resolution>0.1</resolution>
              </range>
            </ray>
          </sensor>
          <sensor name='wall_sensor' type='ray'>
            <pose frame=''>0.09 -0.12 0.059 0 0 -1</pose>
            <ray>
              <scan>
                <horizontal>
                  <samples>1</samples>
                  <resolution>1</resolution>
                  <min_angle>0</min_angle>
                  <max_angle>0</max_angle>
                </horizontal>
                <vertical>
                  <samples>1</samples>
                  <min_angle>0</min_angle>
                  <max_angle>0</max_angle>
                </vertical>
              </scan>
              <range>
                <min>0.016</min>
                <max>0.04</max>
                <resolution>0.1</resolution>
              </range>
            </ray>
          </sensor>
          <self_collide>0</self_collide>
          <kinematic>0</kinematic>
        </link>
        <link name='left_wheel'>
          <pose frame=''>0 0.13 0.032 0 -0 0</pose>
          <inertial>
            <inertia>
              <ixx>0.001</ixx>
              <ixy>0</ixy>
              <ixz>0</ixz>
              <iyy>0.001</iyy>
              <iyz>0</iyz>
              <izz>0.001</izz>
            </inertia>
            <mass>0.01</mass>
          </inertial>
          <collision name='collision'>
            <pose frame=''>0 0 0 -0 1.5707 1.5707</pose>
            <geometry>
              <cylinder>
                <radius>0.033</radius>
                <length>0.023</length>
              </cylinder>
            </geometry>
            <surface>
              <friction>
                <ode>
                  <mu>10</mu>
                  <mu2>10</mu2>
                  <fdir1>0 0 0</fdir1>
                  <slip1>0</slip1>
                  <slip2>0</slip2>
                </ode>
                <torsional>
                  <ode/>
                </torsional>
              </friction>
              <contact>
                <ode/>
              </contact>
              <bounce/>
            </surface>
            <max_contacts>10</max_contacts>
          </collision>
          <visual name='visual'>
            <pose frame=''>0 0 0 -0 1.5707 1.5707</pose>
            <geometry>
              <cylinder>
                <radius>0.033</radius>
                <length>0.023</length>
              </cylinder>
            </geometry>
          </visual>
          <self_collide>0</self_collide>
          <kinematic>0</kinematic>
        </link>
        <link name='right_wheel'>
          <pose frame=''>0 -0.13 0.032 0 -0 0</pose>
          <inertial>
            <inertia>
              <ixx>0.001</ixx>
              <ixy>0</ixy>
              <ixz>0</ixz>
              <iyy>0.001</iyy>
              <iyz>0</iyz>
              <izz>0.001</izz>
            </inertia>
            <mass>0.01</mass>
          </inertial>
          <collision name='collision'>
            <pose frame=''>0 0 0 -0 1.5707 1.5707</pose>
            <geometry>
              <cylinder>
                <radius>0.033</radius>
                <length>0.023</length>
              </cylinder>
            </geometry>
            <surface>
              <friction>
                <ode>
                  <mu>10</mu>
                  <mu2>10</mu2>
                  <fdir1>0 0 0</fdir1>
                  <slip1>0</slip1>
                  <slip2>0</slip2>
                </ode>
                <torsional>
                  <ode/>
                </torsional>
              </friction>
              <contact>
                <ode/>
              </contact>
              <bounce/>
            </surface>
            <max_contacts>10</max_contacts>
          </collision>
          <visual name='visual'>
            <pose frame=''>0 0 0 -0 1.5707 1.5707</pose>
            <geometry>
              <cylinder>
                <radius>0.033</radius>
                <length>0.023</length>
              </cylinder>
            </geometry>
          </visual>
          <self_collide>0</self_collide>
          <kinematic>0</kinematic>
        </link>
        <joint name='left_wheel' type='revolute'>
          <parent>base</parent>
          <child>left_wheel</child>
          <axis>
            <xyz>0 1 0</xyz>
            <use_parent_model_frame>1</use_parent_model_frame>
            <limit>
              <lower>-1e+16</lower>
              <upper>1e+16</upper>
            </limit>
            <dynamics>
              <spring_reference>0</spring_reference>
              <spring_stiffness>0</spring_stiffness>
            </dynamics>
          </axis>
        </joint>
        <joint name='right_wheel' type='revolute'>
          <parent>base</parent>
          <child>right_wheel</child>
          <axis>
            <xyz>0 1 0</xyz>
            <use_parent_model_frame>1</use_parent_model_frame>
            <limit>
              <lower>-1e+16</lower>
              <upper>1e+16</upper>
            </limit>
            <dynamics>
              <spring_reference>0</spring_reference>
              <spring_stiffness>0</spring_stiffness>
            </dynamics>
          </axis>
        </joint>
        <pose frame=''>-0 0 0 0 -0 0</pose>
      </model>
      <static>0</static>
      <allow_auto_disable>1</allow_auto_disable>
      <pose frame=''>-0.042538 0.133888 0 0 -0 0</pose>
    </model>
    <state world_name='default'>
      <sim_time>18 602000000</sim_time>
      <real_time>18 652553748</real_time>
      <wall_time>1628097623 242339202</wall_time>
      <iterations>18602</iterations>
      <model name='ground_plane'>
        <pose frame=''>0 0 0 0 -0 0</pose>
        <scale>1 1 1</scale>
        <link name='link'>
          <pose frame=''>0 0 0 0 -0 0</pose>
          <velocity>0 0 0 0 -0 0</velocity>
          <acceleration>0 0 0 0 -0 0</acceleration>
          <wrench>0 0 0 0 -0 0</wrench>
        </link>
      </model>
      <model name='two_wheeled_robot'>
        <pose frame=''>-0.042538 0.133888 0 0 -0 0</pose>
        <scale>1 1 1</scale>
        <model name='create'>
          <pose frame=''>-0.042538 0.133888 0 0 -0 0</pose>
          <scale>1 1 1</scale>
          <link name='base'>
            <pose frame=''>-0.042538 0.133888 0 0 -0 0</pose>
            <velocity>0 0 0 0 -0 0</velocity>
            <acceleration>0 0 0 0 -0 0</acceleration>
            <wrench>0 0 0 0 -0 0</wrench>
          </link>
          <link name='left_wheel'>
            <pose frame=''>-0.042538 0.263888 0.032 0 -0 0</pose>
            <velocity>0 0 0 0 -0 0</velocity>
            <acceleration>0 0 0 0 -0 0</acceleration>
            <wrench>0 0 0 0 -0 0</wrench>
          </link>
          <link name='right_wheel'>
            <pose frame=''>-0.042538 0.003888 0.032 0 -0 0</pose>
            <velocity>0 0 0 0 -0 0</velocity>
            <acceleration>0 0 0 0 -0 0</acceleration>
            <wrench>0 0 0 0 -0 0</wrench>
          </link>
        </model>
      </model>
      <light name='sun'>
        <pose frame=''>0 0 10 0 -0 0</pose>
      </light>
    </state>
    <gui fullscreen='0'>
      <camera name='user_camera'>
        <pose frame=''>0.963449 -2.54735 1.71709 -0 0.403643 1.96419</pose>
        <view_controller>orbit</view_controller>
        <projection_type>perspective</projection_type>
      </camera>
    </gui>
  </world>
</sdf>
